Workbook

Sheet Products
A1: # | B1: Product | C1: Category | D1: Rice Type | E1: Tagline | F1: Variants | G1: Image | H1: Product Page URL | I1: Image URL
A2: 1 | B2: Savitri Ashirvaad | C2: Premium Rice | D2: Sona Masuri | E2: Taste the difference | F2: =COUNTIF(Variants!$A$2:$A$107,B2) | G2: =_xlfn.IMAGE("https://savitrigroup.in/wp-content/uploads/2018/02/ashirvaad-1.jpg") | H2: https://savitrigroup.in/products/rice/premium-rice/savitri-ashirvaad/ | I2: https://savitrigroup.in/wp-content/uploads/2018/02/ashirvaad-1.jpg
A3: 2 | B3: Savitri Anugrahaa | C3: Premium Rice | D3: Sona Masuri | E3: Traditional rice of India | F3: =COUNTIF(Variants!$A$2:$A$107,B3) | G3: =_xlfn.IMAGE("https://savitrigroup.in/wp-content/uploads/2025/07/savitri_anugraha-green.jpg") | H3: https://savitrigroup.in/products/rice/premium-rice/savitri-anugrahaa/ | I3: https://savitrigroup.in/wp-content/uploads/2025/07/savitri_anugraha-green.jpg
A4: 3 | B4: Abhivrudhi | C4: Premium Rice | D4: Sona Masuri | E4: Traditional rice of India | F4: =COUNTIF(Variants!$A$2:$A$107,B4) | G4: =_xlfn.IMAGE("https://savitrigroup.in/wp-content/uploads/2025/04/abhivrudhi-bronze.jpg") | H4: https://savitrigroup.in/products/rice/premium-rice/abhivrudhi/ | I4: https://savitrigroup.in/wp-content/uploads/2025/04/abhivrudhi-bronze.jpg
A5: 4 | B5: Savitri Ashirvaad Premium | C5: Special Rice | D5: HMT | E5: Treasure of taste | F5: =COUNTIF(Variants!$A$2:$A$107,B5) | G5: =_xlfn.IMAGE("https://savitrigroup.in/wp-content/uploads/2018/02/premium-1.jpg") | H5: https://savitrigroup.in/products/rice/special-rice/ashirvaad-premium/ | I5: https://savitrigroup.in/wp-content/uploads/2018/02/premium-1.jpg
A6: 5 | B6: Savitri Ashirvaad Indian Special | C6: Special Rice | D6: Kolam | E6: Probably the best rice in the world | F6: =COUNTIF(Variants!$A$2:$A$107,B6) | G6: =_xlfn.IMAGE("https://savitrigroup.in/wp-content/uploads/2018/02/indian-special-1.jpg") | H6: https://savitrigroup.in/products/rice/special-rice/ashirvaad-indian-special/ | I6: https://savitrigroup.in/wp-content/uploads/2018/02/indian-special-1.jpg
A7: 6 | B7: Savitri Ashirvaad Sanjeevani | C7: Special Rice | D7: Jeera RNR/48 | E7: Rice for life | F7: =COUNTIF(Variants!$A$2:$A$107,B7) | G7: =_xlfn.IMAGE("https://savitrigroup.in/wp-content/uploads/2021/08/Sanjeevani-1.png") | H7: https://savitrigroup.in/products/rice/special-rice/ashirvaad-sanjeevani/ | I7: https://savitrigroup.in/wp-content/uploads/2021/08/Sanjeevani-1.png
A8: 7 | B8: Sambramam | C8: Special Rice | D8: Jeera | E8: Premium quality rice | F8: =COUNTIF(Variants!$A$2:$A$107,B8) | G8: =_xlfn.IMAGE("https://savitrigroup.in/wp-content/uploads/2025/04/krupa-sambramam-blue.jpg") | H8: https://savitrigroup.in/products/rice/special-rice/sambramam/ | I8: https://savitrigroup.in/wp-content/uploads/2025/04/krupa-sambramam-blue.jpg
A9: 8 | B9: Amruth Gold | C9: Consumer Rice Range | D9: Sona Masuri | E9: Enrich your life | F9: =COUNTIF(Variants!$A$2:$A$107,B9) | G9: =_xlfn.IMAGE("https://savitrigroup.in/wp-content/uploads/2018/02/amruth-1.jpg") | H9: https://savitrigroup.in/products/rice/consumer-rice-range/amruth-gold/ | I9: https://savitrigroup.in/wp-content/uploads/2018/02/amruth-1.jpg
A10: 9 | B10: Avani | C10: Consumer Rice Range | D10: Jeera | E10: Premium quality rice | F10: =COUNTIF(Variants!$A$2:$A$107,B10) | G10: =_xlfn.IMAGE("https://savitrigroup.in/wp-content/uploads/2025/04/avani-blue.jpg") | H10: https://savitrigroup.in/products/rice/consumer-rice-range/avani/ | I10: https://savitrigroup.in/wp-content/uploads/2025/04/avani-blue.jpg
A11: 10 | B11: Akshata | C11: Consumer Rice Range | D11: Sona Masuri | E11: Bless of life | F11: =COUNTIF(Variants!$A$2:$A$107,B11) | G11: =_xlfn.IMAGE("https://savitrigroup.in/wp-content/uploads/2018/02/akshata-1.jpg") | H11: https://savitrigroup.in/products/rice/consumer-rice-range/akshata/ | I11: https://savitrigroup.in/wp-content/uploads/2018/02/akshata-1.jpg
A12: 11 | B12: Akshaya | C12: Consumer Rice Range | D12: Jeera | E12: Embrace pure living | F12: =COUNTIF(Variants!$A$2:$A$107,B12) | G12: =_xlfn.IMAGE("https://savitrigroup.in/wp-content/uploads/2025/04/akshaya-silk-blue.jpg") | H12: https://savitrigroup.in/products/rice/consumer-rice-range/akshaya/ | I12: https://savitrigroup.in/wp-content/uploads/2025/04/akshaya-silk-blue.jpg
A13: 12 | B13: Family | C13: Economical Rice Range | D13: Sona Masuri | E13: Everyone's choice | F13: =COUNTIF(Variants!$A$2:$A$107,B13) | G13: =_xlfn.IMAGE("https://savitrigroup.in/wp-content/uploads/2018/02/family-1.jpg") | H13: https://savitrigroup.in/products/rice/economical-rice-range/family/ | I13: https://savitrigroup.in/wp-content/uploads/2018/02/family-1.jpg
A14: 13 | B14: Kutumbh | C14: Economical Rice Range | D14: Sona Masuri | E14: Nourish your gatherings | F14: =COUNTIF(Variants!$A$2:$A$107,B14) | G14: =_xlfn.IMAGE("https://savitrigroup.in/wp-content/uploads/2025/04/kutumbh-blue.jpg") | H14: https://savitrigroup.in/products/rice/economical-rice-range/kutumbh/ | I14: https://savitrigroup.in/wp-content/uploads/2025/04/kutumbh-blue.jpg
A15: 14 | B15: Ayush | C15: Economical Rice Range | D15: IR 64 | E15: Power to life | F15: =COUNTIF(Variants!$A$2:$A$107,B15) | G15: =_xlfn.IMAGE("https://savitrigroup.in/wp-content/uploads/2018/02/auysh-1.jpg") | H15: https://savitrigroup.in/products/rice/economical-rice-range/ayush/ | I15: https://savitrigroup.in/wp-content/uploads/2018/02/auysh-1.jpg
A16: 15 | B16: Krupa | C16: Economical Rice Range | D16: Sona Masuri | E16: Premium quality rice | F16: =COUNTIF(Variants!$A$2:$A$107,B16) | G16: =_xlfn.IMAGE("https://savitrigroup.in/wp-content/uploads/2025/04/krupa-blue.jpg") | H16: https://savitrigroup.in/products/rice/economical-rice-range/krupa/ | I16: https://savitrigroup.in/wp-content/uploads/2025/04/krupa-blue.jpg
A17: 16 | B17: Ajantha | C17: Economical Rice Range | D17: Sona Masuri | E17: Just the best | F17: =COUNTIF(Variants!$A$2:$A$107,B17) | G17: =_xlfn.IMAGE("https://savitrigroup.in/wp-content/uploads/2018/02/ajanta-1.jpg") | H17: https://savitrigroup.in/products/rice/economical-rice-range/ajantha/ | I17: https://savitrigroup.in/wp-content/uploads/2018/02/ajanta-1.jpg
A18: 17 | B18: Elephanta | C18: Economical Rice Range | D18: Sona Masuri | E18: Eat strong, be strong | F18: =COUNTIF(Variants!$A$2:$A$107,B18) | G18: =_xlfn.IMAGE("https://savitrigroup.in/wp-content/uploads/2018/02/elephanta-1.jpg") | H18: https://savitrigroup.in/products/rice/economical-rice-range/elephanta/ | I18: https://savitrigroup.in/wp-content/uploads/2018/02/elephanta-1.jpg
A19: 18 | B19: Ellora | C19: Economical Rice Range | D19: Sona Masuri | E19: Strong and beautiful | F19: =COUNTIF(Variants!$A$2:$A$107,B19) | G19: =_xlfn.IMAGE("https://savitrigroup.in/wp-content/uploads/2018/02/ellora-1.jpg") | H19: https://savitrigroup.in/products/rice/economical-rice-range/ellora/ | I19: https://savitrigroup.in/wp-content/uploads/2018/02/ellora-1.jpg
A20: 19 | B20: Ship | C20: Broken Rice Range | D20: Broken rice | E20: Imperial choice rice | F20: =COUNTIF(Variants!$A$2:$A$107,B20) | G20: =_xlfn.IMAGE("https://savitrigroup.in/wp-content/uploads/2025/04/ship-green.jpg") | H20: https://savitrigroup.in/products/rice/broken-rice-range/ship/ | I20: https://savitrigroup.in/wp-content/uploads/2025/04/ship-green.jpg
A21: 20 | B21: Train | C21: Broken Rice Range | D21: Broken rice | E21: Take good care of you | F21: =COUNTIF(Variants!$A$2:$A$107,B21) | G21: =_xlfn.IMAGE("https://savitrigroup.in/wp-content/uploads/2025/04/train-blue.jpg") | H21: https://savitrigroup.in/products/rice/broken-rice-range/train/ | I21: https://savitrigroup.in/wp-content/uploads/2025/04/train-blue.jpg
A22: 21 | B22: Lorry | C22: Broken Rice Range | D22: Broken rice | E22: Takes good care of you | F22: =COUNTIF(Variants!$A$2:$A$107,B22) | G22: =_xlfn.IMAGE("https://savitrigroup.in/wp-content/uploads/2018/02/lorry-1.jpg") | H22: https://savitrigroup.in/products/rice/broken-rice-range/lorry/ | I22: https://savitrigroup.in/wp-content/uploads/2018/02/lorry-1.jpg
A23: 22 | B23: Tractor | C23: Broken Rice Range | D23: Sona broken | E23: The best you can get | F23: =COUNTIF(Variants!$A$2:$A$107,B23) | G23: =_xlfn.IMAGE("https://savitrigroup.in/wp-content/uploads/2018/02/tractor-1.jpg") | H23: https://savitrigroup.in/products/rice/broken-rice-range/tractor/ | I23: https://savitrigroup.in/wp-content/uploads/2018/02/tractor-1.jpg
A24: 23 | B24: Auto | C24: Broken Rice Range | D24: Sona broken | E24: You will like it | F24: =COUNTIF(Variants!$A$2:$A$107,B24) | G24: =_xlfn.IMAGE("https://savitrigroup.in/wp-content/uploads/2018/02/auto-1.jpg") | H24: https://savitrigroup.in/products/rice/broken-rice-range/auto/ | I24: https://savitrigroup.in/wp-content/uploads/2018/02/auto-1.jpg
A25: 24 | B25: Scooter | C25: Broken Rice Range | D25: Broken rice | E25: Don't cook it, scooter it | F25: =COUNTIF(Variants!$A$2:$A$107,B25) | G25: =_xlfn.IMAGE("https://savitrigroup.in/wp-content/uploads/2018/02/scooter-1.jpg") | H25: https://savitrigroup.in/products/rice/broken-rice-range/scooter/ | I25: https://savitrigroup.in/wp-content/uploads/2018/02/scooter-1.jpg
A26: 25 | B26: Kangaroo | C26: Broken Rice Range | D26: Broken rice | E26: Feel good with Kangaroo | F26: =COUNTIF(Variants!$A$2:$A$107,B26) | G26: =_xlfn.IMAGE("https://savitrigroup.in/wp-content/uploads/2018/02/kangaroo-1.jpg") | H26: https://savitrigroup.in/products/rice/broken-rice-range/kangaroo/ | I26: https://savitrigroup.in/wp-content/uploads/2018/02/kangaroo-1.jpg
A27: 26 | B27: Savitri Ashirvaad Idly Rawa | C27: Rice By-Products | D27: By-product | E27: Rice by-product | F27: =COUNTIF(Variants!$A$2:$A$107,B27) | G27: No image on website | H27: https://savitrigroup.in/products/rice-by-products/ashirvaad-idli-rawa/
A28: 27 | B28: Savitri Ashirvaad Rice Flour | C28: Rice By-Products | D28: By-product | E28: Rice by-product | F28: =COUNTIF(Variants!$A$2:$A$107,B28) | G28: No image on website | H28: https://savitrigroup.in/products/rice-by-products/ashirvaad-rice-flour/
A29: 28 | B29: Savitri Ashirvaad Poha | C29: Rice By-Products | D29: By-product | E29: Rice by-product | F29: =COUNTIF(Variants!$A$2:$A$107,B29) | G29: No image on website | H29: https://savitrigroup.in/products/rice-by-products/ashirvaad-poha/
A30: 29 | B30: Savitri Ashirvaad Rice Rawa | C30: Rice By-Products | D30: By-product | E30: Rice by-product | F30: =COUNTIF(Variants!$A$2:$A$107,B30) | G30: No image on website | H30: https://savitrigroup.in/products/rice-by-products/ashirvaad-rice-rawa/
A31: 30 | B31: Savitri Ashirvaad Murmure | C31: Rice By-Products | D31: By-product | E31: Rice by-product | F31: =COUNTIF(Variants!$A$2:$A$107,B31) | G31: No image on website | H31: https://savitrigroup.in/products/rice-by-products/ashirvaad-murmure/
A32: 31 | B32: Savitri Ashirvaad Puttu Podi | C32: Rice By-Products | D32: By-product | E32: Rice by-product | F32: =COUNTIF(Variants!$A$2:$A$107,B32) | G32: No image on website | H32: https://savitrigroup.in/products/rice-by-products/ashirvaad-puttu-podi/
E34: Total variants | F34: =SUM(F2:F32)

Sheet Variants
A1: Product | B1: Category | C1: Rice Type | D1: Variant | E1: Variant Details | F1: Image | G1: Image URL | H1: Variant Page URL
A2: Savitri Ashirvaad | B2: Premium Rice | C2: Sona Masuri | D2: Bronze | E2: New sona steam rice | F2: =_xlfn.IMAGE("https://savitrigroup.in/wp-content/uploads/2018/02/ashirvaad-1.jpg") | G2: https://savitrigroup.in/wp-content/uploads/2018/02/ashirvaad-1.jpg | H2: https://savitrigroup.in/products/rice/premium-rice/savitri-ashirvaad/bronze/
A3: Savitri Ashirvaad | B3: Premium Rice | C3: Sona Masuri | D3: Copper | E3: 6 months old sona rice | F3: =_xlfn.IMAGE("https://savitrigroup.in/wp-content/uploads/2018/02/ashirvaad-2.jpg") | G3: https://savitrigroup.in/wp-content/uploads/2018/02/ashirvaad-2.jpg | H3: https://savitrigroup.in/products/rice/premium-rice/savitri-ashirvaad/copper/
A4: Savitri Ashirvaad | B4: Premium Rice | C4: Sona Masuri | D4: Gold | E4: 1 year old sona rice | F4: =_xlfn.IMAGE("https://savitrigroup.in/wp-content/uploads/2018/02/ashirvaad-3.jpg") | G4: https://savitrigroup.in/wp-content/uploads/2018/02/ashirvaad-3.jpg | H4: https://savitrigroup.in/products/rice/premium-rice/savitri-ashirvaad/gold/
A5: Savitri Ashirvaad | B5: Premium Rice | C5: Sona Masuri | D5: Steel | E5: White sona steam rice | F5: =_xlfn.IMAGE("https://savitrigroup.in/wp-content/uploads/2018/02/ashirvaad-4.jpg") | G5: https://savitrigroup.in/wp-content/uploads/2018/02/ashirvaad-4.jpg | H5: https://savitrigroup.in/products/rice/premium-rice/savitri-ashirvaad/steel/
A6: Savitri Ashirvaad | B6: Premium Rice | C6: Sona Masuri | D6: Platinum | E6: 1 year old raw rice | F6: =_xlfn.IMAGE("https://savitrigroup.in/wp-content/uploads/2018/02/ashirvaad-5.jpg") | G6: https://savitrigroup.in/wp-content/uploads/2018/02/ashirvaad-5.jpg | H6: https://savitrigroup.in/products/rice/premium-rice/savitri-ashirvaad/platinum-2/
A7: Savitri Ashirvaad | B7: Premium Rice | C7: Sona Masuri | D7: Silver | E7: 6 months old raw rice | F7: =_xlfn.IMAGE("https://savitrigroup.in/wp-content/uploads/2018/02/ashirvaad-6.jpg") | G7: https://savitrigroup.in/wp-content/uploads/2018/02/ashirvaad-6.jpg | H7: https://savitrigroup.in/products/rice/premium-rice/savitri-ashirvaad/silver/
A8: Savitri Ashirvaad | B8: Premium Rice | C8: Sona Masuri | D8: Emerald | E8: New half boiled sona masuri rice | F8: =_xlfn.IMAGE("https://savitrigroup.in/wp-content/uploads/2018/02/ashirvaad-7.jpg") | G8: https://savitrigroup.in/wp-content/uploads/2018/02/ashirvaad-7.jpg | H8: https://savitrigroup.in/products/rice/premium-rice/savitri-ashirvaad/emerald/
A9: Savitri Ashirvaad | B9: Premium Rice | C9: Sona Masuri | D9: Sapphire | E9: New full boiled sona masuri rice | F9: =_xlfn.IMAGE("https://savitrigroup.in/wp-content/uploads/2018/02/ashirvaad-9.jpg") | G9: https://savitrigroup.in/wp-content/uploads/2018/02/ashirvaad-9.jpg | H9: https://savitrigroup.in/products/rice/premium-rice/savitri-ashirvaad/sapphire/
A10: Savitri Ashirvaad | B10: Premium Rice | C10: Sona Masuri | D10: Diamond | E10: Half boiled 1 year old sona masuri rice | F10: =_xlfn.IMAGE("https://savitrigroup.in/wp-content/uploads/2018/02/ashirvaad-10.jpg") | G10: https://savitrigroup.in/wp-content/uploads/2018/02/ashirvaad-10.jpg | H10: https://savitrigroup.in/products/rice/premium-rice/savitri-ashirvaad/diamond/
A11: Savitri Anugrahaa | B11: Premium Rice | C11: Sona Masuri | D11: Green | E11: New sona steam rice | F11: =_xlfn.IMAGE("https://savitrigroup.in/wp-content/uploads/2025/07/savitri_anugraha-green.jpg") | G11: https://savitrigroup.in/wp-content/uploads/2025/07/savitri_anugraha-green.jpg | H11: https://savitrigroup.in/products/rice/premium-rice/savitri-anugrahaa/green/
A12: Savitri Anugrahaa | B12: Premium Rice | C12: Sona Masuri | D12: Red | E12: Sona steam general rice | F12: =_xlfn.IMAGE("https://savitrigroup.in/wp-content/uploads/2025/07/savitri_anugraha-red.jpg") | G12: https://savitrigroup.in/wp-content/uploads/2025/07/savitri_anugraha-red.jpg | H12: https://savitrigroup.in/products/rice/premium-rice/savitri-anugrahaa/orange/
A13: Savitri Anugrahaa | B13: Premium Rice | C13: Sona Masuri | D13: Brown | E13: 6 months old sona rice | F13: =_xlfn.IMAGE("https://savitrigroup.in/wp-content/uploads/2025/07/savitri_anugraha-brown.jpg") | G13: https://savitrigroup.in/wp-content/uploads/2025/07/savitri_anugraha-brown.jpg | H13: https://savitrigroup.in/products/rice/premium-rice/savitri-anugrahaa/brown/
A14: Savitri Anugrahaa | B14: Premium Rice | C14: Sona Masuri | D14: Yellow | E14: White sona steam rice | F14: =_xlfn.IMAGE("https://savitrigroup.in/wp-content/uploads/2025/07/savitri_anugraha-yellow.jpg") | G14: https://savitrigroup.in/wp-content/uploads/2025/07/savitri_anugraha-yellow.jpg | H14: https://savitrigroup.in/products/rice/premium-rice/savitri-anugrahaa/yellow/
A15: Savitri Anugrahaa | B15: Premium Rice | C15: Sona Masuri | D15: Black | E15: 1 year old sona masuri rice | F15: =_xlfn.IMAGE("https://savitrigroup.in/wp-content/uploads/2025/07/savitri_anugraha-black-1.jpg") | G15: https://savitrigroup.in/wp-content/uploads/2025/07/savitri_anugraha-black-1.jpg | H15: https://savitrigroup.in/products/rice/premium-rice/savitri-anugrahaa/black/
A16: Savitri Anugrahaa | B16: Premium Rice | C16: Sona Masuri | D16: Blue | E16: New sona masuri rice | F16: =_xlfn.IMAGE("https://savitrigroup.in/wp-content/uploads/2025/07/savitri_anugraha-blue.jpg") | G16: https://savitrigroup.in/wp-content/uploads/2025/07/savitri_anugraha-blue.jpg | H16: https://savitrigroup.in/products/rice/premium-rice/savitri-anugrahaa/blue/
A17: Savitri Anugrahaa | B17: Premium Rice | C17: Sona Masuri | D17: Grey | E17: New half boiled sona masuri rice | F17: =_xlfn.IMAGE("https://savitrigroup.in/wp-content/uploads/2025/07/savitri_anugraha-grey.jpg") | G17: https://savitrigroup.in/wp-content/uploads/2025/07/savitri_anugraha-grey.jpg | H17: https://savitrigroup.in/products/rice/premium-rice/savitri-anugrahaa/grey/
A18: Savitri Anugrahaa | B18: Premium Rice | C18: Sona Masuri | D18: Orange | E18: Full boiled 1 year old sona masuri rice | F18: =_xlfn.IMAGE("https://savitrigroup.in/wp-content/uploads/2025/07/savitri_anugraha-orange.jpg") | G18: https://savitrigroup.in/wp-content/uploads/2025/07/savitri_anugraha-orange.jpg | H18: https://savitrigroup.in/products/rice/premium-rice/savitri-anugrahaa/red/
A19: Savitri Anugrahaa | B19: Premium Rice | C19: Sona Masuri | D19: Purple | E19: New full boiled sona masuri rice | F19: =_xlfn.IMAGE("https://savitrigroup.in/wp-content/uploads/2025/07/savitri_anugraha-purple.jpg") | G19: https://savitrigroup.in/wp-content/uploads/2025/07/savitri_anugraha-purple.jpg | H19: https://savitrigroup.in/products/rice/premium-rice/savitri-anugrahaa/purple/
A20: Savitri Anugrahaa | B20: Premium Rice | C20: Sona Masuri | D20: White | E20: Half boiled 1 year old sona masuri rice | F20: =_xlfn.IMAGE("https://savitrigroup.in/wp-content/uploads/2025/07/savitri_anugraha-white.jpg") | G20: https://savitrigroup.in/wp-content/uploads/2025/07/savitri_anugraha-white.jpg | H20: https://savitrigroup.in/products/rice/premium-rice/savitri-anugrahaa/white/
A21: Abhivrudhi | B21: Premium Rice | C21: Sona Masuri | D21: Bronze | E21: Traditional rice of India | F21: =_xlfn.IMAGE("https://savitrigroup.in/wp-content/uploads/2025/04/abhivrudhi-bronze.jpg") | G21: https://savitrigroup.in/wp-content/uploads/2025/04/abhivrudhi-bronze.jpg
A22: Abhivrudhi | B22: Premium Rice | C22: Sona Masuri | D22: Copper | E22: Traditional rice of India | F22: =_xlfn.IMAGE("https://savitrigroup.in/wp-content/uploads/2025/04/abhivrudhi-copper.jpg") | G22: https://savitrigroup.in/wp-content/uploads/2025/04/abhivrudhi-copper.jpg
A23: Abhivrudhi | B23: Premium Rice | C23: Sona Masuri | D23: Diamond | E23: Traditional rice of India | F23: =_xlfn.IMAGE("https://savitrigroup.in/wp-content/uploads/2025/04/abhivrudhi-diamond.jpg") | G23: https://savitrigroup.in/wp-content/uploads/2025/04/abhivrudhi-diamond.jpg
A24: Abhivrudhi | B24: Premium Rice | C24: Sona Masuri | D24: Emerald | E24: Traditional rice of India | F24: =_xlfn.IMAGE("https://savitrigroup.in/wp-content/uploads/2025/04/abhivrudhi-emerald.jpg") | G24: https://savitrigroup.in/wp-content/uploads/2025/04/abhivrudhi-emerald.jpg
A25: Abhivrudhi | B25: Premium Rice | C25: Sona Masuri | D25: Gold | E25: Traditional rice of India | F25: =_xlfn.IMAGE("https://savitrigroup.in/wp-content/uploads/2025/04/abhivrudhi-gold.jpg") | G25: https://savitrigroup.in/wp-content/uploads/2025/04/abhivrudhi-gold.jpg
A26: Abhivrudhi | B26: Premium Rice | C26: Sona Masuri | D26: Platinum | E26: Traditional rice of India | F26: =_xlfn.IMAGE("https://savitrigroup.in/wp-content/uploads/2025/04/abhivrudhi-platinum.jpg") | G26: https://savitrigroup.in/wp-content/uploads/2025/04/abhivrudhi-platinum.jpg
A27: Abhivrudhi | B27: Premium Rice | C27: Sona Masuri | D27: Ruby | E27: Traditional rice of India | F27: =_xlfn.IMAGE("https://savitrigroup.in/wp-content/uploads/2025/04/abhivrudhi-ruby.jpg") | G27: https://savitrigroup.in/wp-content/uploads/2025/04/abhivrudhi-ruby.jpg
A28: Abhivrudhi | B28: Premium Rice | C28: Sona Masuri | D28: Sapphire | E28: Traditional rice of India | F28: =_xlfn.IMAGE("https://savitrigroup.in/wp-content/uploads/2025/04/abhivrudhi-sapphire.jpg") | G28: https://savitrigroup.in/wp-content/uploads/2025/04/abhivrudhi-sapphire.jpg
A29: Abhivrudhi | B29: Premium Rice | C29: Sona Masuri | D29: Silver | E29: Traditional rice of India | F29: =_xlfn.IMAGE("https://savitrigroup.in/wp-content/uploads/2025/04/abhivrudhi-silver.jpg") | G29: https://savitrigroup.in/wp-content/uploads/2025/04/abhivrudhi-silver.jpg
A30: Abhivrudhi | B30: Premium Rice | C30: Sona Masuri | D30: Steel | E30: Traditional rice of India | F30: =_xlfn.IMAGE("https://savitrigroup.in/wp-content/uploads/2025/04/abhivrudhi-steel.jpg") | G30: https://savitrigroup.in/wp-content/uploads/2025/04/abhivrudhi-steel.jpg
A31: Savitri Ashirvaad Premium | B31: Special Rice | C31: HMT | D31: Pack 1 | E31: New HMT rice | F31: =_xlfn.IMAGE("https://savitrigroup.in/wp-content/uploads/2018/02/premium-1.jpg") | G31: https://savitrigroup.in/wp-content/uploads/2018/02/premium-1.jpg | H31: https://savitrigroup.in/products/rice/special-rice/ashirvaad-premium/hmt-rice-1/
A32: Savitri Ashirvaad Premium | B32: Special Rice | C32: HMT | D32: Pack 2 | E32: New HMT rice | F32: =_xlfn.IMAGE("https://savitrigroup.in/wp-content/uploads/2018/02/premium-2.jpg") | G32: https://savitrigroup.in/wp-content/uploads/2018/02/premium-2.jpg | H32: https://savitrigroup.in/products/rice/special-rice/ashirvaad-premium/hmt-rice-2/
A33: Savitri Ashirvaad Premium | B33: Special Rice | C33: HMT | D33: Pack 3 | E33: New HMT rice | F33: =_xlfn.IMAGE("https://savitrigroup.in/wp-content/uploads/2018/02/premium-3.jpg") | G33: https://savitrigroup.in/wp-content/uploads/2018/02/premium-3.jpg | H33: https://savitrigroup.in/products/rice/special-rice/ashirvaad-premium/hmt-rice-3/
A34: Savitri Ashirvaad Indian Special | B34: Special Rice | C34: Kolam | D34: Pack 1 | E34: Kolam rice | F34: =_xlfn.IMAGE("https://savitrigroup.in/wp-content/uploads/2018/02/indian-special-1.jpg") | G34: https://savitrigroup.in/wp-content/uploads/2018/02/indian-special-1.jpg | H34: https://savitrigroup.in/products/rice/special-rice/ashirvaad-indian-special/kolam-rice-1/
A35: Savitri Ashirvaad Indian Special | B35: Special Rice | C35: Kolam | D35: Pack 2 | E35: Kolam rice | F35: =_xlfn.IMAGE("https://savitrigroup.in/wp-content/uploads/2018/02/indian-special-2.jpg") | G35: https://savitrigroup.in/wp-content/uploads/2018/02/indian-special-2.jpg | H35: https://savitrigroup.in/products/rice/special-rice/ashirvaad-indian-special/kolam-rice-2/
A36: Savitri Ashirvaad Indian Special | B36: Special Rice | C36: Kolam | D36: Pack 3 | E36: Kolam rice | F36: =_xlfn.IMAGE("https://savitrigroup.in/wp-content/uploads/2018/02/indian-special-3.jpg") | G36: https://savitrigroup.in/wp-content/uploads/2018/02/indian-special-3.jpg | H36: https://savitrigroup.in/products/rice/special-rice/ashirvaad-indian-special/kolam-rice-3/
A37: Savitri Ashirvaad Indian Special | B37: Special Rice | C37: Kolam | D37: Pack 4 | E37: Kolam rice | F37: =_xlfn.IMAGE("https://savitrigroup.in/wp-content/uploads/2021/08/Indian-Special.png") | G37: https://savitrigroup.in/wp-content/uploads/2021/08/Indian-Special.png | H37: https://savitrigroup.in/products/rice/special-rice/ashirvaad-indian-special/kolam-rice-4/
A38: Savitri Ashirvaad Sanjeevani | B38: Special Rice | C38: Jeera RNR/48 | D38: Pack 1 | E38: RNR/48 jeera rice | F38: =_xlfn.IMAGE("https://savitrigroup.in/wp-content/uploads/2021/08/Sanjeevani-1.png") | G38: https://savitrigroup.in/wp-content/uploads/2021/08/Sanjeevani-1.png | H38: https://savitrigroup.in/products/rice/special-rice/ashirvaad-sanjeevani/jeera-rice-1/
A39: Savitri Ashirvaad Sanjeevani | B39: Special Rice | C39: Jeera RNR/48 | D39: Pack 2 | E39: RNR/48 jeera rice | F39: =_xlfn.IMAGE("https://savitrigroup.in/wp-content/uploads/2021/08/Sanjeevani-2.png") | G39: https://savitrigroup.in/wp-content/uploads/2021/08/Sanjeevani-2.png | H39: https://savitrigroup.in/products/rice/special-rice/ashirvaad-sanjeevani/jeera-rice-2/
A40: Savitri Ashirvaad Sanjeevani | B40: Special Rice | C40: Jeera RNR/48 | D40: Pack 3 | E40: RNR/48 jeera rice | F40: =_xlfn.IMAGE("https://savitrigroup.in/wp-content/uploads/2021/08/Sanjeevani-4.png") | G40: https://savitrigroup.in/wp-content/uploads/2021/08/Sanjeevani-4.png | H40: https://savitrigroup.in/products/rice/special-rice/ashirvaad-sanjeevani/jeera-rice-3/
...

Sheet Notes
A1: Item | B1: Note
A2: Source | B2: savitrigroup.in product pages, fetched 5 Oct 2026 (Premium, Special, Consumer, Economical, Broken rice ranges and Rice By-Products menu).
A3: Coverage | B3: 31 products (25 rice brands + 6 rice by-products) and 106 rice variants.
A4: Images | B4: Images are not stored in the file. The Image columns use Excel's IMAGE() function and load live from savitrigroup.in. They work in Microsoft 365 / Excel 2021+ and Google Sheets, and need an internet connection. In older Excel, use the Image URL column links instead.
A5: Image gaps | B5: The six rice by-products have no images or detail pages with content on the website, so they have no image.
A6: Variant details | B6: Taken from each variant's caption on the website (e.g. rice grade/age/process). Where the website gives no distinct variant name (marked 'Pack 1', 'Pack 2' ...), the number is only the order shown on the page.
A7: Not published | B7: The website does not list pack sizes, prices, or nutrition details, so none are included.
A8: Product names | B8: All product names are brands shown on the Savitri Group website.
